<?xml version="1.0" ?>
<!-- =================================================================================== -->
<!-- |    This document was autogenerated by xacro from robot_wheel.xacro              | -->
<!-- |    EDITING THIS FILE BY HAND IS NOT RECOMMENDED                                 | -->
<!-- =================================================================================== -->
<robot name="magicdog">
  <material name="black">
    <color rgba="0.0 0.0 0.0 1.0"/>
  </material>
  <material name="blue">
    <color rgba="0.0 0.0 0.8 1.0"/>
  </material>
  <material name="green">
    <color rgba="0.0 0.8 0.0 1.0"/>
  </material>
  <material name="grey">
    <color rgba="0.2 0.2 0.2 1.0"/>
  </material>
  <material name="silver">
    <color rgba="0.9137254901960784 0.9137254901960784 0.8470588235294118 1.0"/>
  </material>
  <material name="orange">
    <color rgba="1.0 0.4235294117647059 0.0392156862745098 1.0"/>
  </material>
  <material name="brown">
    <color rgba="0.8705882352941177 0.8117647058823529 0.7647058823529411 1.0"/>
  </material>
  <material name="red">
    <color rgba="0.8 0.0 0.0 1.0"/>
  </material>
  <material name="white">
    <color rgba="1.0 1.0 1.0 1.0"/>
  </material>
  <link name="base">
    <visual>
      <origin rpy="0 0 0" xyz="0 0 0"/>
      <geometry>
        <mesh filename="../meshes/magicdog_base.stl" scale="1 1 1"/>
        <!-- <box size="0.327 0.194 0.114"/> -->
      </geometry>
      <material name="silver"/>
    </visual>
    <collision>
      <origin rpy="0 0 0" xyz="0 0 0"/>
      <geometry>
        <box size="0.327 0.194 0.114"/>
      </geometry>
    </collision>
    <inertial>
      <origin rpy="0 0 0" xyz="0.030789072 -0.0015929272 0.019370127"/>
      <mass value="8.6470505"/>
      <inertia ixx="0.047071341" ixy="-0.0013391533" ixz="-0.031639906" iyy="0.14560398" iyz="-0.00026207612" izz="0.14388143"/>
    </inertial>
  </link>

  <joint name="head_joint" type="fixed" dont_collapse="true">
    <origin rpy="0.0 0.349 0.0" xyz="0.21518 0.0 0.09654"/>
    <parent link="base"/>
    <child link="head"/>
  </joint>
  <link name="head">
    <inertial>
      <mass value="0.001"/>
      <origin rpy="0 0 0" xyz="0 0 0"/>
      <inertia ixx="0.000001" ixy="0" ixz="0" iyy="0.000001" iyz="0" izz="0.000001"/>
    </inertial>
    <collision>
      <origin rpy="0.0 0.0 0.0" xyz="0.03 0 0.052"/>
      <geometry>
        <box size="0.16 0.1 0.13"/>
      </geometry>
    </collision>
  </link>

  <joint name="FR_hip_joint" type="revolute">
    <origin rpy="0 0 0" xyz="0.220365 -0.04998785 0"/>
    <parent link="base"/>
    <child link="FR_hip"/>
    <axis xyz="1 0 0"/>
    <dynamics damping="0" friction="0"/>
    <limit effort="25" lower="-0.6457718232379019" upper="0.7853981633974483" velocity="22"/>
  </joint>
  <link name="FR_hip">
    <visual>
      <origin rpy="-1.5707963267948966 -1.5707963267948966 0 " xyz="0 0 0"/>
      <geometry>
        <mesh filename="../meshes/magicdog_abad.stl" scale="1 1 1"/>
      </geometry>
      <material name="grey"/>
    </visual>
    <collision>
      <origin rpy="1.5707963267948966 0 0" xyz="0 -0.075 0"/>
      <geometry>
        <cylinder length="0.07" radius="0.05"/>
      </geometry>
    </collision>
    <inertial>
      <origin rpy="0 0 0" xyz="-0.034672887 0.0039130227 0.0"/>
      <mass value="0.35996359"/>
      <inertia ixx="0.00010289238" ixy="-3.0677028e-05" ixz="0" iyy="0.00047667644" iyz="-0.0" izz="0.00046973335"/>
    </inertial>
  </link>
  <joint name="FR_thigh_joint" type="revolute">
    <origin rpy="0 0 0" xyz="0 -0.099 0"/>
    <parent link="FR_hip"/>
    <child link="FR_thigh"/>
    <axis xyz="0 1 0"/>
    <dynamics damping="0" friction="0"/>
    <limit effort="25" lower="-1.2653637076958888" upper="3.6215581978882336" velocity="22"/>
  </joint>
  <link name="FR_thigh">
    <visual>
      <origin rpy="3.141592653589793 -1.5707963267948966 0" xyz="0 0 0"/>
      <geometry>
        <mesh filename="../meshes/magicdog_hip_right.stl" scale="1 1 1"/>
      </geometry>
      <material name="orange"/>
    </visual>
    <collision>
      <origin rpy="0 1.5707963267948966 0" xyz="-0.018 0 -0.11000000000000001"/>
      <geometry>
        <box size="0.1 0.03 0.04"/>
      </geometry>
    </collision>
    <inertial>
      <origin rpy="0 0 0" xyz="-0.0033473586 0.031436598 -0.032009477"/>
      <mass value="1.5725954"/>
      <inertia ixx="0.0089600443" ixy="-0.00020991626" ixz="-0.00051137678" iyy="0.0078167414" iyz="-0.0017655451" izz="0.0028432732"/>
    </inertial>
  </link>
  <joint name="FR_calf_joint" type="revolute">
    <origin rpy="0 0 0" xyz="0 0 -0.2"/>
    <parent link="FR_thigh"/>
    <child link="FR_calf"/>
    <axis xyz="0 1 0"/>
    <dynamics damping="0" friction="0"/>
    <limit effort="37.5" lower="-2.3668409986295105" upper="-0.39461894387591795" velocity="15"/>
  </joint>
  <link name="FR_calf">
    <visual>
      <origin rpy="0 0 0" xyz="0 0 0"/>
      <geometry>
        <mesh filename="../meshes/magicdog_right_knee_wheel.STL" scale="1 1 1"/>
      </geometry>
      <material name="red"/>
    </visual>
    <collision>
      <origin rpy="0 1.5707963267948966 0" xyz="0 0 -0.14625"/>
      <!-- <origin rpy="0 0 0" xyz="0 0 0"/> -->
      <geometry>
        <box size="0.28885 0.025 0.025"/>
        <!-- <box size="0.28885 0.016 0.016"/> -->
        <!-- <mesh filename="../meshes/magicdog_right_knee_wheel.STL" scale="1 1 1"/> -->
      </geometry>
    </collision>
    <inertial>
      <origin rpy="0 0 0" xyz="0.005260 -0.006732 -0.202313"/>
      <mass value="1.018534"/>
      <inertia ixx="0.006748" ixy="-0.000037" ixz="-0.000341" iyy="0.007322" iyz="-0.000283" izz="0.000811"/>
    </inertial>
  </link>
  <joint name="FR_wheel_joint" type="revolute">
    <origin rpy="0 0 0" xyz="0 0 -0.24351"/>
    <parent link="FR_calf"/>
    <child link="FR_wheel"/>
    <axis xyz="0 1 0"/>
    <dynamics damping="0" friction="0"/>
    <limit effort="15" velocity="35"/>
  </joint>
  <link name="FR_wheel">
    <visual>
      <origin rpy="0 0 0" xyz="0 0 0"/>
      <geometry>
        <mesh filename="../meshes/magicdog_right_wheel.STL" scale="1 1 1"/>
      </geometry>
      <material name="grey"/>
    </visual>
    <collision>
      <origin rpy="1.5707963267948966 0 0" xyz="0 -0.045 0"/>
      <geometry>
        <cylinder length="0.030" radius="0.090"/>
      </geometry>
    </collision>
    <inertial>
      <origin rpy="0 0 0" xyz="0 -0.037340 0"/>
      <mass value="0.510931"/>
      <inertia ixx="0.000707" ixy="0" ixz="0" iyy="0.001321" iyz="0" izz="0.000707"/>
    </inertial>
  </link>
  <joint name="FL_hip_joint" type="revolute">
    <origin rpy="0 0 0" xyz="0.220365 0.04998785 0"/>
    <parent link="base"/>
    <child link="FL_hip"/>
    <axis xyz="1 0 0"/>
    <dynamics damping="0" friction="0"/>
    <limit effort="25" lower="-0.7853981633974483" upper="0.6457718232379019" velocity="22"/>
  </joint>
  <link name="FL_hip">
    <visual>
      <origin rpy="1.5707963267948966 1.5707963267948966 0" xyz="0 0 0"/>
      <geometry>
        <mesh filename="../meshes/magicdog_abad.stl" scale="1 1 1"/>
      </geometry>
      <material name="grey"/>
    </visual>
    <collision>
      <origin rpy="1.5707963267948966 0 0" xyz="0 0.075 0"/>
      <geometry>
        <cylinder length="0.07" radius="0.05"/>
      </geometry>
    </collision>
    <inertial>
      <origin rpy="0 0 0" xyz="-0.034672887 -0.0039130227 0.0"/>
      <mass value="0.35996359"/>
      <inertia ixx="0.00010289238" ixy="3.0677028e-05" ixz="0" iyy="0.00047667644" iyz="0.0" izz="0.00046973335"/>
    </inertial>
  </link>
  <joint name="FL_thigh_joint" type="revolute">
    <origin rpy="0 0 0" xyz="0 0.099 0"/>
    <parent link="FL_hip"/>
    <child link="FL_thigh"/>
    <axis xyz="0 1 0"/>
    <dynamics damping="0" friction="0"/>
    <limit effort="25" lower="-1.2653637076958888" upper="3.6215581978882336" velocity="22"/>
  </joint>
  <link name="FL_thigh">
    <visual>
      <origin rpy="3.141592653589793 -1.5707963267948966 0" xyz="0 0 0"/>
      <geometry>
        <mesh filename="../meshes/magicdog_hip.stl" scale="1 1 1"/>
      </geometry>
      <material name="orange"/>
    </visual>
    <collision>
      <origin rpy="0 1.5707963267948966 0" xyz="-0.018 0 -0.11000000000000001"/>
      <geometry>
        <box size="0.1 0.03 0.04"/>
      </geometry>
    </collision>
    <inertial>
      <origin rpy="0 0 0" xyz="-0.0033473586 -0.031436598 -0.032009477"/>
      <mass value="1.5725954"/>
      <inertia ixx="0.0089600443" ixy="0.00020991626" ixz="-0.00051137678" iyy="0.0078167414" iyz="0.0017655451" izz="0.0028432732"/>
    </inertial>
  </link>
  <joint name="FL_calf_joint" type="revolute">
    <origin rpy="0 0 0" xyz="0 0 -0.2"/>
    <parent link="FL_thigh"/>
    <child link="FL_calf"/>
    <axis xyz="0 1 0"/>
    <dynamics damping="0" friction="0"/>
    <limit effort="37.5" lower="-2.3668409986295105" upper="-0.39461894387591795" velocity="15"/>
  </joint>
  <link name="FL_calf">
    <visual>
      <origin rpy="0 0 0" xyz="0 0 0"/>
      <geometry>
        <mesh filename="../meshes/magicdog_left_knee_wheel_.STL" scale="1 1 1"/>
      </geometry>
      <material name="red"/>
    </visual>
    <collision>
      <origin rpy="0 1.5707963267948966 0" xyz="0 0 -0.14625"/>
      <!-- <origin rpy="0 0 0" xyz="0 0 0"/> -->
      <geometry>
        <box size="0.28885 0.025 0.025"/>
        <!-- <mesh filename="../meshes/magicdog_left_knee_wheel_.STL" scale="1 1 1"/> -->
      </geometry>
    </collision>
    <inertial>
      <origin rpy="0 0 0" xyz="0.005351 0.003694 -0.202438"/>
      <mass value="1.018534"/>
      <inertia ixx="0.006799" ixy="0.000019" ixz="-0.000335" iyy="0.007357" iyz="0.000154" izz="0.000844"/>
    </inertial>
  </link>
  <joint name="FL_wheel_joint" type="revolute">
    <origin rpy="0 0 0" xyz="0 0 -0.24351"/>
    <parent link="FL_calf"/>
    <child link="FL_wheel"/>
    <axis xyz="0 1 0"/>
    <dynamics damping="0" friction="0"/>
    <limit effort="15" velocity="35"/>
  </joint>
  <link name="FL_wheel">
    <visual>
      <origin rpy="0 0 0" xyz="0 0 0"/>
      <geometry>
        <mesh filename="../meshes/magicdog_left_wheel.STL" scale="1 1 1"/>
      </geometry>
      <material name="grey"/>
    </visual>
    <collision>
      <origin rpy="1.5707963267948966 0 0" xyz="0 0.045 0"/>
      <geometry>
        <cylinder length="0.030" radius="0.090"/>
      </geometry>
    </collision>
    <inertial>
      <origin rpy="0 0 0" xyz="0 0.037340 0"/>
      <mass value="0.510931"/>
      <inertia ixx="0.000707" ixy="0" ixz="0" iyy="0.001321" iyz="0" izz="0.000707"/>
    </inertial>
  </link>
  <joint name="RR_hip_joint" type="revolute">
    <origin rpy="0 0 0" xyz="-0.220365 -0.04998785 0"/>
    <parent link="base"/>
    <child link="RR_hip"/>
    <axis xyz="1 0 0"/>
    <dynamics damping="0" friction="0"/>
    <limit effort="25" lower="-0.6457718232379019" upper="0.7853981633974483" velocity="22"/>
  </joint>
  <link name="RR_hip">
    <visual>
      <origin rpy="-1.5707963267948966 1.5707963267948966 0" xyz="0 0 0"/>
      <geometry>
        <mesh filename="../meshes/magicdog_abad.stl" scale="1 1 1"/>
      </geometry>
      <material name="grey"/>
    </visual>
    <collision>
      <origin rpy="1.5707963267948966 0 0" xyz="0 -0.075 0"/>
      <geometry>
        <cylinder length="0.07" radius="0.05"/>
      </geometry>
    </collision>
    <inertial>
      <origin rpy="0 0 0" xyz="0.034672887 0.0039130227 0.0"/>
      <mass value="0.35996359"/>
      <inertia ixx="0.00010289238" ixy="3.0677028e-05" ixz="0" iyy="0.00047667644" iyz="-0.0" izz="0.00046973335"/>
    </inertial>
  </link>
  <joint name="RR_thigh_joint" type="revolute">
    <origin rpy="0 0 0" xyz="0 -0.099 0"/>
    <parent link="RR_hip"/>
    <child link="RR_thigh"/>
    <axis xyz="0 1 0"/>
    <dynamics damping="0" friction="0"/>
    <limit effort="25" lower="-1.2653637076958888" upper="3.6215581978882336" velocity="22"/>
  </joint>
  <link name="RR_thigh">
    <visual>
      <origin rpy="3.141592653589793 -1.5707963267948966 0" xyz="0 0 0"/>
      <geometry>
        <mesh filename="../meshes/magicdog_hip_right.stl" scale="1 1 1"/>
      </geometry>
      <material name="orange"/>
    </visual>
    <collision>
      <origin rpy="0 1.5707963267948966 0" xyz="-0.018 0 -0.11000000000000001"/>
      <geometry>
        <box size="0.1 0.03 0.04"/>
      </geometry>
    </collision>
    <inertial>
      <origin rpy="0 0 0" xyz="-0.0033473586 0.031436598 -0.032009477"/>
      <mass value="1.5725954"/>
      <inertia ixx="0.0089600443" ixy="-0.00020991626" ixz="-0.00051137678" iyy="0.0078167414" iyz="-0.0017655451" izz="0.0028432732"/>
    </inertial>
  </link>
  <joint name="RR_calf_joint" type="revolute">
    <origin rpy="0 0 0" xyz="0 0 -0.2"/>
    <parent link="RR_thigh"/>
    <child link="RR_calf"/>
    <axis xyz="0 1 0"/>
    <dynamics damping="0" friction="0"/>
    <limit effort="37.5" lower="-2.3668409986295105" upper="-0.39461894387591795" velocity="15"/>
  </joint>
  <link name="RR_calf">
    <visual>
      <origin rpy="0 0 0" xyz="0 0 0"/>
      <geometry>
        <mesh filename="../meshes/magicdog_right_knee_wheel.STL" scale="1 1 1"/>
      </geometry>
      <material name="red"/>
    </visual>
    <collision>
      <origin rpy="0 1.5707963267948966 0" xyz="0 0 -0.14625"/>
      <!-- <origin rpy="0 0 0" xyz="0 0 0"/> -->
      <geometry>
        <box size="0.28885 0.025 0.025"/>
        <!-- <mesh filename="../meshes/magicdog_right_knee_wheel.STL" scale="1 1 1"/> -->
      </geometry>
    </collision>
    <inertial>
      <origin rpy="0 0 0" xyz="0.005260 -0.006732 -0.202313"/>
      <mass value="1.018534"/>
      <inertia ixx="0.006748" ixy="-0.000037" ixz="-0.000341" iyy="0.007322" iyz="-0.000283" izz="0.000811"/>
    </inertial>
  </link>
  <joint name="RR_wheel_joint" type="revolute">
    <origin rpy="0 0 0" xyz="0 0 -0.24351"/>
    <parent link="RR_calf"/>
    <child link="RR_wheel"/>
    <axis xyz="0 1 0"/>
    <dynamics damping="0" friction="0"/>
    <limit effort="15" velocity="35"/>
  </joint>
  <link name="RR_wheel">
    <visual>
      <origin rpy="0 0 0" xyz="0 0 0"/>
      <geometry>
        <mesh filename="../meshes/magicdog_right_wheel.STL" scale="1 1 1"/>
      </geometry>
      <material name="grey"/>
    </visual>
    <collision>
      <origin rpy="1.5707963267948966 0 0" xyz="0 -0.045 0"/>
      <geometry>
        <cylinder length="0.030" radius="0.090"/>
      </geometry>
    </collision>
    <inertial>
      <origin rpy="0 0 0" xyz="0 -0.037340 0"/>
      <mass value="0.510931"/>
      <inertia ixx="0.000707" ixy="0" ixz="0" iyy="0.001321" iyz="0" izz="0.000707"/>
    </inertial>
  </link>
  <joint name="RL_hip_joint" type="revolute">
    <origin rpy="0 0 0" xyz="-0.220365 0.04998785 0"/>
    <parent link="base"/>
    <child link="RL_hip"/>
    <axis xyz="1 0 0"/>
    <dynamics damping="0" friction="0"/>
    <limit effort="25" lower="-0.7853981633974483" upper="0.6457718232379019" velocity="22"/>
  </joint>
  <link name="RL_hip">
    <visual>
      <origin rpy="1.5707963267948966 -1.5707963267948966 0" xyz="0 0 0"/>
      <geometry>
        <mesh filename="../meshes/magicdog_abad.stl" scale="1 1 1"/>
      </geometry>
      <material name="grey"/>
    </visual>
    <collision>
      <origin rpy="1.5707963267948966 0 0" xyz="0 0.075 0"/>
      <geometry>
        <cylinder length="0.07" radius="0.05"/>
      </geometry>
    </collision>
    <inertial>
      <origin rpy="0 0 0" xyz="0.034672887 -0.0039130227 0.0"/>
      <mass value="0.35996359"/>
      <inertia ixx="0.00010289238" ixy="-3.0677028e-05" ixz="0" iyy="0.00047667644" iyz="0.0" izz="0.00046973335"/>
    </inertial>
  </link>
  <joint name="RL_thigh_joint" type="revolute">
    <origin rpy="0 0 0" xyz="0 0.099 0"/>
    <parent link="RL_hip"/>
    <child link="RL_thigh"/>
    <axis xyz="0 1 0"/>
    <dynamics damping="0" friction="0"/>
    <limit effort="25" lower="-1.2653637076958888" upper="3.6215581978882336" velocity="22"/>
  </joint>
  <link name="RL_thigh">
    <visual>
      <origin rpy="3.141592653589793 -1.5707963267948966 0" xyz="0 0 0"/>
      <geometry>
        <mesh filename="../meshes/magicdog_hip.stl" scale="1 1 1"/>
      </geometry>
      <material name="orange"/>
    </visual>
    <collision>
      <origin rpy="0 1.5707963267948966 0" xyz="-0.018 0 -0.11000000000000001"/>
      <geometry>
        <box size="0.1 0.03 0.04"/>
      </geometry>
    </collision>
    <inertial>
      <origin rpy="0 0 0" xyz="-0.0033473586 -0.031436598 -0.032009477"/>
      <mass value="1.5725954"/>
      <inertia ixx="0.0089600443" ixy="0.00020991626" ixz="-0.00051137678" iyy="0.0078167414" iyz="0.0017655451" izz="0.0028432732"/>
    </inertial>
  </link>
  <joint name="RL_calf_joint" type="revolute">
    <origin rpy="0 0 0" xyz="0 0 -0.2"/>
    <parent link="RL_thigh"/>
    <child link="RL_calf"/>
    <axis xyz="0 1 0"/>
    <dynamics damping="0" friction="0"/>
    <limit effort="37.5" lower="-2.3668409986295105" upper="-0.39461894387591795" velocity="15"/>
  </joint>
  <link name="RL_calf">
    <visual>
      <origin rpy="0 0 0" xyz="0 0 0"/>
      <geometry>
        <mesh filename="../meshes/magicdog_left_knee_wheel_.STL" scale="1 1 1"/>
      </geometry>
      <material name="red"/>
    </visual>
    <collision>
      <origin rpy="0 1.5707963267948966 0" xyz="0 0 -0.14625"/>
      <!-- <origin rpy="0 0 0" xyz="0 0 0"/> -->
      <geometry>
        <box size="0.28885 0.025 0.025"/>
        <!-- <mesh filename="../meshes/magicdog_left_knee_wheel_.STL" scale="1 1 1"/> -->
      </geometry>
    </collision>
    <inertial>
      <origin rpy="0 0 0" xyz="0.005351 0.003694 -0.202438"/>
      <mass value="1.018534"/>
      <inertia ixx="0.006799" ixy="0.000019" ixz="-0.000335" iyy="0.007357" iyz="0.000154" izz="0.000844"/>
    </inertial>
  </link>
  <joint name="RL_wheel_joint" type="revolute">
    <origin rpy="0 0 0" xyz="0 0 -0.24351"/>
    <parent link="RL_calf"/>
    <child link="RL_wheel"/>
    <axis xyz="0 1 0"/>
    <dynamics damping="0" friction="0"/>
    <limit effort="15" velocity="35"/>
  </joint>
  <link name="RL_wheel">
    <visual>
      <origin rpy="0 0 0" xyz="0 0 0"/>
      <geometry>
        <mesh filename="../meshes/magicdog_left_wheel.STL" scale="1 1 1"/>
      </geometry>
      <material name="grey"/>
    </visual>
    <collision>
      <origin rpy="1.5707963267948966 0 0" xyz="0 0.045 0"/>
      <geometry>
        <cylinder length="0.030" radius="0.090"/>
      </geometry>
    </collision>
    <inertial>
      <origin rpy="0 0 0" xyz="0 0.037340 0"/>
      <mass value="0.510931"/>
      <inertia ixx="0.000707" ixy="0" ixz="0" iyy="0.001321" iyz="0" izz="0.000707"/>
    </inertial>
  </link>
</robot>